<?xml version="1.0" encoding="utf-8"?>
<!-- This URDF was automatically created by SolidWorks to URDF Exporter! Originally created by Stephen Brawner (brawner@gmail.com) 
     Commit Version: 1.6.0-4-g7f85cfe  Build Version: 1.6.7995.38578
     For more information, please see http://wiki.ros.org/sw_urdf_exporter -->
<robot
  name="urdf1_pkg">
  <link name="dummy">
  </link>
  <joint name="dummy_joint" type="fixed">
    <parent link="dummy"/>
    <child link="base_link"/>
  </joint>
  
  
  <link
    name="base_link">
    <inertial>
      <origin
        xyz="-1.7945E-17 0 0.0225"
        rpy="0 0 0" />
      <mass
        value="2.5133" />
      <inertia
        ixx="0.0076236"
        ixy="1.0719E-50"
        ixz="-2.7271E-18"
        iyy="0.0076236"
        iyz="-1.9427E-35"
        izz="0.012566" />
    </inertial>
    <visual>
      <origin
        xyz="0 0 0"
        rpy="0 0 0" />
      <geometry>
        <mesh
          filename="package://urdf1_pkg/meshes/base_link.STL" />
      </geometry>
      <material
        name="">
        <color
          rgba="1 1 1 1" />
      </material>
    </visual>
    <collision>
      <origin
        xyz="0 0 0"
        rpy="0 0 0" />
      <geometry>
        <mesh
          filename="package://urdf1_pkg/meshes/base_link.STL" />
      </geometry>
    </collision>
  </link>
  
  
  
  <link
    name="right">
    <inertial>
      <origin
        xyz="-3.6088E-19 6.9389E-18 -0.0075"
        rpy="0 0 0" />
      <mass
        value="0.057727" />
      <inertia
        ixx="1.8761E-05"
        ixy="-4.272E-38"
        ixz="-1.8053E-23"
        iyy="1.8761E-05"
        iyz="6.6704E-22"
        izz="3.5358E-05" />
    </inertial>
    <visual>
      <origin
        xyz="0 0 0"
        rpy="0 0 0" />
      <geometry>
        <mesh
          filename="package://urdf1_pkg/meshes/right.STL" />
      </geometry>
      <material
        name="">
        <color
          rgba="1 1 1 1" />
      </material>
    </visual>
    <collision>
      <origin
        xyz="0 0 0"
        rpy="0 0 0" />
      <geometry>
        <mesh
          filename="package://urdf1_pkg/meshes/right.STL" />
      </geometry>
    </collision>
  </link>
  
  
  
  
  
  
  <joint
    name="base_r_wheel_joint"
    type="continuous">
    <origin
      xyz="0 -0.115 0"
      rpy="1.5707963267949 0 0" />
    <parent
      link="base_link" />
    <child
      link="right" />
    <axis
      xyz="0 0 1" />
  </joint>
  
  
  
  
  <link
    name="left">
    <inertial>
      <origin
        xyz="-2.6797E-19 3.4694E-18 0.0075"
        rpy="0 0 0" />
      <mass
        value="0.057727" />
      <inertia
        ixx="1.8761E-05"
        ixy="-1.747E-21"
        ixz="8.1084E-24"
        iyy="1.8761E-05"
        iyz="6.3683E-22"
        izz="3.5358E-05" />
    </inertial>
    <visual>
      <origin
        xyz="0 0 0"
        rpy="0 0 0" />
      <geometry>
        <mesh
          filename="package://urdf1_pkg/meshes/left.STL" />
      </geometry>
      <material
        name="">
        <color
          rgba="1 1 1 1" />
      </material>
    </visual>
    <collision>
      <origin
        xyz="0 0 0"
        rpy="0 0 0" />
      <geometry>
        <mesh
          filename="package://urdf1_pkg/meshes/left.STL" />
      </geometry>
    </collision>
  </link>
  
  
  
  
  <joint
    name="base_l_wheel_joint"
    type="continuous">
    <origin
      xyz="0 0.115 0"
      rpy="1.5707963267949 0 0" />
    <parent
      link="base_link" />
    <child
      link="left" />
    <axis
      xyz="0 0 1" />
  </joint>
  <link
    name="front">
    <inertial>
      <origin
        xyz="0 -2.3404E-19 0"
        rpy="0 0 0" />
      <mass
        value="0.0017671" />
      <inertia
        ixx="3.9761E-08"
        ixy="2.8689E-24"
        ixz="-3.229E-24"
        iyy="3.9761E-08"
        iyz="-4.2493E-24"
        izz="3.9761E-08" />
    </inertial>
    <visual>
      <origin
        xyz="0 0 0"
        rpy="0 0 0" />
      <geometry>
        <mesh
          filename="package://urdf1_pkg/meshes/front.STL" />
      </geometry>
      <material
        name="">
        <color
          rgba="1 1 1 1" />
      </material>
    </visual>
    <collision>
      <origin
        xyz="0 0 0"
        rpy="0 0 0" />
      <geometry>
        <mesh
          filename="package://urdf1_pkg/meshes/front.STL" />
      </geometry>
    </collision>
  </link>
  <joint
    name="f_driven"
    type="continuous">
    <origin
      xyz="0.07 0 -0.025"
      rpy="0 0 0" />
    <parent
      link="base_link" />
    <child
      link="front" />
    <axis
      xyz="1 1 1" />
  </joint>
  <link
    name="back">
    <inertial>
      <origin
        xyz="0 1.1702E-19 8.6736E-19"
        rpy="0 0 0" />
      <mass
        value="0.0017671" />
      <inertia
        ixx="3.9761E-08"
        ixy="2.0466E-24"
        ixz="-4.9043E-24"
        iyy="3.9761E-08"
        iyz="-3.4696E-24"
        izz="3.9761E-08" />
    </inertial>
    <visual>
      <origin
        xyz="0 0 0"
        rpy="0 0 0" />
      <geometry>
        <mesh
          filename="package://urdf1_pkg/meshes/back.STL" />
      </geometry>
      <material
        name="">
        <color
          rgba="1 1 1 1" />
      </material>
    </visual>
    <collision>
      <origin
        xyz="0 0 0"
        rpy="0 0 0" />
      <geometry>
        <mesh
          filename="package://urdf1_pkg/meshes/back.STL" />
      </geometry>
    </collision>
  </link>
  <joint
    name="back_driven"
    type="continuous">
    <origin
      xyz="-0.07 0 -0.025"
      rpy="0 0 0" />
    <parent
      link="base_link" />
    <child
      link="back" />
    <axis
      xyz="1 1 1" />
  </joint>
</robot>